<?xml version="1.0" ?>
<robot name="manipulator" xmlns:xacro="http://ros.org/wiki/xacro">

 <material name="black">
  <color rgba="0.0 0.0 0.0 1.0"/>
 </material>
 <material name="blue">
  <color rgba="0.5 0.75 1.0 1.0"/>
 </material>
 <material name="brown">
  <color rgba="0.5 0.5 0.5 1.0"/>
 </material>
 <material name="yellow" >
  <color rgba="0.9803921568627451 0.996078431372549 0.29411764705882354 1.0"/>
 </material>

 <link name="base_footprint"/>

 <joint name="base_joint" type="fixed">
  <parent link="base_footprint"/>
  <child link="base_link"/>
  <origin rpy="0 0 0" xyz="0.0 0.0 0.0"/>
 </joint>

 <link name="base_link">
  <collision>
   <geometry>
    <box size="0.38 0.25 0.13"/>
   </geometry>
  </collision>

  <visual>
   <origin rpy="0 0 0" xyz="0 0 0.11"/>
   <geometry>
    <box size="0.38 0.25 0.13"/>
   </geometry>
   <material name="blue"/>
  </visual>
 </link>

 <link name="back_wheels">
  <inertial>
   <mass value="0.2"/>
   <origin rpy="0 1.5707 1.5707" xyz="0 0.135 0"/>
   <inertia ixx="0.00052666666" ixy="0" ixz="0" iyy="0.00052666666" iyz="0" izz="0.001"/>
  </inertial>

  <collision>
   <origin rpy="0 1.5707 1.5707" xyz="0 0.135 0"/>
   <geometry>
    <cylinder length="0.03" radius="0.05"/>
   </geometry>
  </collision>

  <visual>
   <origin rpy="0 1.5707 1.5707" xyz="0 0.135 0"/>
   <geometry>
    <cylinder length="0.03" radius="0.05"/>
   </geometry>
   <material name="brown"/>
  </visual>

  <!-- Inertial for the second back wheel -->
  <inertial>
   <mass value="0.2"/>
   <origin rpy="0 1.5707 1.5707" xyz="0 -0.135 0"/>
   <inertia ixx="0.00052666666" ixy="0" ixz="0" iyy="0.00052666666" iyz="0" izz="0.001"/>
  </inertial>

  <collision>
   <origin rpy="0 1.5707 1.5707" xyz="0 -0.135 0"/>
   <geometry>
    <cylinder length="0.03" radius="0.05"/>
   </geometry>
  </collision>

  <visual>
   <origin rpy="0 1.5707 1.5707" xyz="0 -0.135 0"/>
   <geometry>
    <cylinder length="0.03" radius="0.05"/>
   </geometry>
   <material name="brown"/>
  </visual>
 </link>

 <joint name="joint_back_wheels" type="continuous">
  <origin rpy="0 0 0" xyz="-0.12 0 0.05"/>
  <parent link="base_link"/>
  <child link="back_wheels"/>
  <axis rpy="0 0 0" xyz="0 1 0"/>
  <limit effort="1000.0" velocity="1.0"/>
 </joint>

 <link name="front_wheels">
  <inertial>
   <mass value="0.2"/>
   <origin rpy="0 1.5707 1.5707" xyz="0 0.135 0"/>
   <inertia ixx="0.00052666666" ixy="0" ixz="0" iyy="0.00052666666" iyz="0" izz="0.001"/>
  </inertial>

  <collision>
   <origin rpy="0 1.5707 1.5707" xyz="0 0.135 0"/>
   <geometry>
    <cylinder length="0.03" radius="0.05"/>
   </geometry>
  </collision>

  <visual>
   <origin rpy="0 1.5707 1.5707" xyz="0 0.135 0"/>
   <geometry>
    <cylinder length="0.03" radius="0.05"/>
   </geometry>
   <material name="brown"/>
  </visual>

  <!-- Inertial for the second front wheel -->
  <inertial>
   <mass value="0.2"/>
   <origin rpy="0 1.5707 1.5707" xyz="0 -0.135 0"/>
   <inertia ixx="0.00052666666" ixy="0" ixz="0" iyy="0.00052666666" iyz="0" izz="0.001"/>
  </inertial>

  <collision>
   <origin rpy="0 1.5707 1.5707" xyz="0 -0.135 0"/>
   <geometry>
    <cylinder length="0.03" radius="0.05"/>
   </geometry>
  </collision>

  <visual>
   <origin rpy="0 1.5707 1.5707" xyz="0 -0.135 0"/>
   <geometry>
    <cylinder length="0.03" radius="0.05"/>
   </geometry>
   <material name="brown"/>
  </visual>
 </link>

 <joint name="joint_front_wheels" type="continuous">
  <origin rpy="0 0 0" xyz="0.12 0 0.05"/>
  <parent link="base_link"/>
  <child link="front_wheels"/>
  <axis rpy="0 0 0" xyz="0 1 0"/>
  <limit effort="1000.0" velocity="1.0"/>
 </joint>

 <link name="upper_link">
  <inertial>
   <origin xyz="0 0 0" rpy="0 0 0"/>
   <mass value="1"/>
   <inertia ixx="0.02" ixy="0" ixz="0" iyy="0.02" iyz="0" izz="0.02"/>
  </inertial>
  <visual>
   <origin xyz="0 0 0" rpy="0 0 0"/>
   <geometry>
    <box size="0.23 0.25 0.11"/>
   </geometry>
   <material name="blue"/>
  </visual>
  <collision>
   <origin xyz="0 0 0" rpy="0 0 0"/>
   <geometry>
    <box size="0.23 0.25 0.11"/>
   </geometry>
  </collision>
 </link>

 <joint name="joint_upper_link" type="fixed">
  <origin xyz="-0.075 0 0.22" rpy="0 0 0"/>
  <parent link="base_link"/>
  <child link="upper_link"/>
 </joint>

 <link name="laser">
  <inertial>
   <origin xyz="0 0 0" rpy="0 0 0"/>
   <mass value="1"/>
   <inertia ixx="0.02" ixy="0" ixz="0" iyy="0.02" iyz="0" izz="0.02"/>
  </inertial>
  <visual>
   <origin xyz="0 0 0" rpy="0 0 0"/>
   <geometry>
    <cylinder radius="0.07" length="0.06"/>
   </geometry>
   <material name="black"/>
  </visual>
  <collision>
   <origin xyz="0 0 0" rpy="0 0 0"/>
   <geometry>
    <cylinder length="0.03" radius="0.06"/>
   </geometry>
  </collision>
 </link>

 <joint name="joint_laser" type="fixed">
  <origin xyz="0 0 0.05" rpy="0 0 3.14159"/>
  <parent link="upper_link"/>
  <child link="laser"/>
 </joint>

</robot>